Workbook

Sheet Form Responses 1
A1: Timestamp | B1: Email id | C1: Name | D1: Code | E1: Score | F1: Sent | G1: Error | H1: Contact number | I1: College | J1: Are you a member of Equinox ? | K1: Which module are you most interested in? | L1: What are your expectations from this course?
A2: 46167.553 | B2: ayush.biswas@iitg.ac.in | C2: Ayush Biswas | D2: ="AE-"&TEXT(ROW()-1,"0000") -> AE-0001 | E2: {=IFERROR(XLOOKUP(D2,'Astronomy 101 Week 1 Quiz (Resp'!F:F,'Astronomy 101 Week 1 Quiz (Resp'!E:E),0)} -> 0 | F2: YES | H2: 7439112615 | I2: IITG | J2: No | K2: Theoretical Module, Computational Module, Observational Module
A3: 46167.558 | B3: tejas.khanna@iitg.ac.in | C3: Tejas Khanna | D3: ="AE-"&TEXT(ROW()-1,"0000") -> AE-0002 | E3: {=IFERROR(XLOOKUP(D3,'Astronomy 101 Week 1 Quiz (Resp'!F:F,'Astronomy 101 Week 1 Quiz (Resp'!E:E),0)} -> 0 | F3: YES | H3: 9555039015 | I3: IITG | J3: No | K3: Theoretical Module, Computational Module
A4: 46167.559 | B4: theajantahajong01@gmail.com | C4: Ajanta Hajong | D4: ="AE-"&TEXT(ROW()-1,"0000") -> AE-0003 | E4: {=IFERROR(XLOOKUP(D4,'Astronomy 101 Week 1 Quiz (Resp'!F:F,'Astronomy 101 Week 1 Quiz (Resp'!E:E),0)} -> 0 | F4: YES | H4: 6000568353 | I4: Cotton University | J4: No | K4: Theoretical Module, Observational Module | L4: To learn some basics of astronomy
A5: 46167.567 | B5: m.jinay@iitg.ac.in | C5: Jinay Mehta | D5: ="AE-"&TEXT(ROW()-1,"0000") -> AE-0004 | E5: {=IFERROR(XLOOKUP(D5,'Astronomy 101 Week 1 Quiz (Resp'!F:F,'Astronomy 101 Week 1 Quiz (Resp'!E:E),0)} -> 44 | F5: YES | H5: 7575842118 | I5: IIT Guwahati | J5: No | K5: Theoretical Module, Computational Module, Observational Module
A6: 46167.571 | B6: s.spoorthi@iitg.ac.in | C6: Spoorthi | D6: ="AE-"&TEXT(ROW()-1,"0000") -> AE-0005 | E6: {=IFERROR(XLOOKUP(D6,'Astronomy 101 Week 1 Quiz (Resp'!F:F,'Astronomy 101 Week 1 Quiz (Resp'!E:E),0)} -> 34 | F6: YES | H6: 8088291584 | I6: IIT GUWAHATI | J6: Yes | K6: Theoretical Module, Computational Module, Observational Module | L6: To learn more about the universe and how to use computational methods
A7: 46167.572 | B7: v.sakshi@iitg.ac.in | C7: Sakshi Vatsa | D7: ="AE-"&TEXT(ROW()-1,"0000") -> AE-0006 | E7: {=IFERROR(XLOOKUP(D7,'Astronomy 101 Week 1 Quiz (Resp'!F:F,'Astronomy 101 Week 1 Quiz (Resp'!E:E),0)} -> 0 | F7: YES | H7: 9999084219 | I7: IIT Guwahati | J7: Yes | K7: Theoretical Module, Computational Module
A8: 46167.574 | B8: raushank1042@iitg.ac.in | C8: Raushan kumar | D8: ="AE-"&TEXT(ROW()-1,"0000") -> AE-0007 | E8: {=IFERROR(XLOOKUP(D8,'Astronomy 101 Week 1 Quiz (Resp'!F:F,'Astronomy 101 Week 1 Quiz (Resp'!E:E),0)} -> 0 | F8: YES | H8: 9279720376 | I8: Iitg | J8: No | K8: Theoretical Module, Computational Module, Observational Module
A9: 46167.575 | B9: h.pasari@iitg.ac.in | C9: Harsh Pasari | D9: ="AE-"&TEXT(ROW()-1,"0000") -> AE-0008 | E9: {=IFERROR(XLOOKUP(D9,'Astronomy 101 Week 1 Quiz (Resp'!F:F,'Astronomy 101 Week 1 Quiz (Resp'!E:E),0)} -> 0 | F9: YES | H9: 8767544954 | I9: IIT G | J9: No | K9: Computational Module, Observational Module | L9: Learn more about how to observer the night sky being a night sky photographer , and how are the various values calculated so accurately despite universe being so random and vast
A10: 46167.575 | B10: y.patel@iitg.ac.in | C10: Yashvardhan Patel | D10: ="AE-"&TEXT(ROW()-1,"0000") -> AE-0009 | E10: {=IFERROR(XLOOKUP(D10,'Astronomy 101 Week 1 Quiz (Resp'!F:F,'Astronomy 101 Week 1 Quiz (Resp'!E:E),0)} -> 39 | F10: YES | H10: 9928810449 | I10: IITG | J10: Yes | K10: Theoretical Module
A11: 46167.577 | B11: anjali.patel@iitg.ac.in | C11: Anjali Patel | D11: ="AE-"&TEXT(ROW()-1,"0000") -> AE-0010 | E11: {=IFERROR(XLOOKUP(D11,'Astronomy 101 Week 1 Quiz (Resp'!F:F,'Astronomy 101 Week 1 Quiz (Resp'!E:E),0)} -> 0 | F11: YES | H11: 9294548721 | I11: IIT Guwahati | J11: No | K11: Theoretical Module, Computational Module, Observational Module | L11: Learn something new and gain some knowledge in this field.
A12: 46167.577 | B12: manvendracharan9@gmail.com | C12: Manvendra Singh Charan | D12: ="AE-"&TEXT(ROW()-1,"0000") -> AE-0011 | E12: {=IFERROR(XLOOKUP(D12,'Astronomy 101 Week 1 Quiz (Resp'!F:F,'Astronomy 101 Week 1 Quiz (Resp'!E:E),0)} -> 27 | F12: YES | H12: 8118800749 | I12: IIT Guwahati | J12: Yes | K12: Computational Module, Observational Module | L12: .
A13: 46167.578 | B13: ashutosh.sharma1@iisi.iitg.ac.in | C13: Ashutosh Sharma | D13: ="AE-"&TEXT(ROW()-1,"0000") -> AE-0012 | E13: {=IFERROR(XLOOKUP(D13,'Astronomy 101 Week 1 Quiz (Resp'!F:F,'Astronomy 101 Week 1 Quiz (Resp'!E:E),0)} -> 0 | F13: YES | H13: 8000290081 | I13: MBM University Jodhpur | J13: No | K13: Computational Module, Observational Module | L13: To learn something new
A14: 46167.578 | B14: j.vidhi@iitg.ac.in | C14: Vidhi joshi | D14: ="AE-"&TEXT(ROW()-1,"0000") -> AE-0013 | E14: {=IFERROR(XLOOKUP(D14,'Astronomy 101 Week 1 Quiz (Resp'!F:F,'Astronomy 101 Week 1 Quiz (Resp'!E:E),0)} -> 11 | F14: YES | H14: 8982520245 | I14: IIT guwahati | J14: Yes | K14: Computational Module
A15: 46167.579 | B15: alokk4009@iitg.ac.in | C15: Alok Kumar | D15: ="AE-"&TEXT(ROW()-1,"0000") -> AE-0014 | E15: {=IFERROR(XLOOKUP(D15,'Astronomy 101 Week 1 Quiz (Resp'!F:F,'Astronomy 101 Week 1 Quiz (Resp'!E:E),0)} -> 44 | F15: YES | H15: 8840990927 | I15: IIT Guwahati | J15: No | K15: Computational Module, Observational Module
A16: 46167.582 | B16: shaurya.jain@iitg.ac.in | C16: Shaurya jain | D16: ="AE-"&TEXT(ROW()-1,"0000") -> AE-0015 | E16: {=IFERROR(XLOOKUP(D16,'Astronomy 101 Week 1 Quiz (Resp'!F:F,'Astronomy 101 Week 1 Quiz (Resp'!E:E),0)} -> 0 | F16: YES | H16: 7849852991 | I16: Iit guwahati | J16: No | K16: Theoretical Module, Computational Module, Observational Module | L16: To learn something new
A17: 46167.584 | B17: abhinavkrish222@gmail.com | C17: Abhinav Krishna L | D17: ="AE-"&TEXT(ROW()-1,"0000") -> AE-0016 | E17: {=IFERROR(XLOOKUP(D17,'Astronomy 101 Week 1 Quiz (Resp'!F:F,'Astronomy 101 Week 1 Quiz (Resp'!E:E),0)} -> 39 | F17: YES | H17: 8867400191 | I17: Iit guwahati | J17: Yes | K17: Theoretical Module, Computational Module, Observational Module
A18: 46167.584 | B18: ketans@iitg.ac.in | C18: Ketan Singh | D18: ="AE-"&TEXT(ROW()-1,"0000") -> AE-0017 | E18: {=IFERROR(XLOOKUP(D18,'Astronomy 101 Week 1 Quiz (Resp'!F:F,'Astronomy 101 Week 1 Quiz (Resp'!E:E),0)} -> 0 | F18: YES | H18: 7389985731 | I18: Indian Institute of Technology Guwahati | J18: No | K18: Theoretical Module, Computational Module, Observational Module
A19: 46167.586 | B19: kaurpsandhu07@gmail.com | C19: Parneet kaur | D19: ="AE-"&TEXT(ROW()-1,"0000") -> AE-0018 | E19: {=IFERROR(XLOOKUP(D19,'Astronomy 101 Week 1 Quiz (Resp'!F:F,'Astronomy 101 Week 1 Quiz (Resp'!E:E),0)} -> 39 | F19: YES | H19: 7014589274 | I19: Indian Institute of technology Guwahati | J19: No | K19: Theoretical Module, Computational Module | L19: I want to learn more about these things
A20: 46167.587 | B20: s.rebbapragada@iitg.ac.in | C20: Sruteesh Satya R | D20: ="AE-"&TEXT(ROW()-1,"0000") -> AE-0019 | E20: {=IFERROR(XLOOKUP(D20,'Astronomy 101 Week 1 Quiz (Resp'!F:F,'Astronomy 101 Week 1 Quiz (Resp'!E:E),0)} -> 0 | F20: YES | H20: 8897540718 | I20: IIT GUWAHATI | J20: Yes | K20: Computational Module
A21: 46167.588 | B21: t.tanisha@iitg.ac.in | C21: Tanisha Tembhare | D21: ="AE-"&TEXT(ROW()-1,"0000") -> AE-0020 | E21: {=IFERROR(XLOOKUP(D21,'Astronomy 101 Week 1 Quiz (Resp'!F:F,'Astronomy 101 Week 1 Quiz (Resp'!E:E),0)} -> 0 | F21: YES | H21: 9604877398 | I21: IIT GUWAHATI | J21: No | K21: Observational Module
A22: 46167.591 | B22: d.joyshmit@iitg.ac.in | C22: Joyshmit Das | D22: ="AE-"&TEXT(ROW()-1,"0000") -> AE-0021 | E22: {=IFERROR(XLOOKUP(D22,'Astronomy 101 Week 1 Quiz (Resp'!F:F,'Astronomy 101 Week 1 Quiz (Resp'!E:E),0)} -> 0 | F22: YES | H22: 9330397631 | I22: IIT Guwahati | J22: No | K22: Theoretical Module, Computational Module | L22: Want to learn how ml concepts are applied to astronomy
A23: 46167.591 | B23: ankan.halder@iitg.ac.in | C23: Ankan Halder | D23: ="AE-"&TEXT(ROW()-1,"0000") -> AE-0022 | E23: {=IFERROR(XLOOKUP(D23,'Astronomy 101 Week 1 Quiz (Resp'!F:F,'Astronomy 101 Week 1 Quiz (Resp'!E:E),0)} -> 0 | F23: YES | H23: 9474359410 | I23: IIT Guwahati | J23: No | K23: Theoretical Module, Observational Module | L23: Learn more about galaxy
A24: 46167.592 | B24: m.jayanth@iitg.ac.in | C24: Jayanth Mummana | D24: ="AE-"&TEXT(ROW()-1,"0000") -> AE-0023 | E24: {=IFERROR(XLOOKUP(D24,'Astronomy 101 Week 1 Quiz (Resp'!F:F,'Astronomy 101 Week 1 Quiz (Resp'!E:E),0)} -> 0 | F24: YES | H24: 7483195454 | I24: IIT Guwahati | J24: No | K24: Computational Module
A25: 46167.593 | B25: anshitakalawat@gmail.com | C25: Anshita Kalawat | D25: ="AE-"&TEXT(ROW()-1,"0000") -> AE-0024 | E25: {=IFERROR(XLOOKUP(D25,'Astronomy 101 Week 1 Quiz (Resp'!F:F,'Astronomy 101 Week 1 Quiz (Resp'!E:E),0)} -> 0 | F25: YES | H25: 9166070127 | I25: IIT Guwahati | J25: No | K25: Computational Module | L25: The computational aspect interests me a lot because it combines astronomy with Python, data analysis, and machine learning, which are highly valuable skills for research and problem-solving. Also , I will be able to learn about telescopes, astrophotography, and real astronomical observations
A26: 46167.594 | B26: ipshitagargbts@gmail.com | C26: Ipshita Garg | D26: ="AE-"&TEXT(ROW()-1,"0000") -> AE-0025 | E26: {=IFERROR(XLOOKUP(D26,'Astronomy 101 Week 1 Quiz (Resp'!F:F,'Astronomy 101 Week 1 Quiz (Resp'!E:E),0)} -> 0 | F26: YES | H26: 9828133998 | I26: IIT Guwahati | J26: Yes | K26: Theoretical Module, Observational Module | L26: To learn more about the universe, how to operate devices and participate in hackathons
A27: 46167.594 | B27: dspb.sr2023@gmail.com | C27: Devi Sri Priya | D27: ="AE-"&TEXT(ROW()-1,"0000") -> AE-0026 | E27: {=IFERROR(XLOOKUP(D27,'Astronomy 101 Week 1 Quiz (Resp'!F:F,'Astronomy 101 Week 1 Quiz (Resp'!E:E),0)} -> 22 | F27: YES | H27: 9441467276 | I27: IIT Guwahati | J27: No | K27: Observational Module | L27: To learn about the universe, things I always wonder about
A28: 46167.598 | B28: h.sinha@iitg.ac.in | C28: Hrishikesh sinha | D28: ="AE-"&TEXT(ROW()-1,"0000") -> AE-0027 | E28: {=IFERROR(XLOOKUP(D28,'Astronomy 101 Week 1 Quiz (Resp'!F:F,'Astronomy 101 Week 1 Quiz (Resp'!E:E),0)} -> 0 | F28: YES | H28: 9239565239 | I28: IIT GUWAHATI | J28: No | K28: Theoretical Module, Computational Module, Observational Module
A29: 46167.604 | B29: n.saumya@iitg.ac.in | C29: Saumya Nawandhar | D29: ="AE-"&TEXT(ROW()-1,"0000") -> AE-0028 | E29: {=IFERROR(XLOOKUP(D29,'Astronomy 101 Week 1 Quiz (Resp'!F:F,'Astronomy 101 Week 1 Quiz (Resp'!E:E),0)} -> 0 | F29: YES | H29: 7977815011 | I29: IIT Guwahati | J29: No | K29: Theoretical Module, Computational Module, Observational Module
A30: 46167.605 | B30: b.karishmita@iitg.ac.in | C30: Karishmita | D30: ="AE-"&TEXT(ROW()-1,"0000") -> AE-0029 | E30: {=IFERROR(XLOOKUP(D30,'Astronomy 101 Week 1 Quiz (Resp'!F:F,'Astronomy 101 Week 1 Quiz (Resp'!E:E),0)} -> 0 | F30: YES | H30: 8822462331 | I30: IIT Guwahati | J30: No | K30: Computational Module
A31: 46167.607 | B31: yuvrajs2264@gmail.com | C31: Yuvraj Singh | D31: ="AE-"&TEXT(ROW()-1,"0000") -> AE-0030 | E31: {=IFERROR(XLOOKUP(D31,'Astronomy 101 Week 1 Quiz (Resp'!F:F,'Astronomy 101 Week 1 Quiz (Resp'!E:E),0)} -> 0 | F31: YES | H31: 8866202885 | I31: IIT Guwahati | J31: No | K31: Theoretical Module
A32: 46167.608 | B32: adityaj4005@iitg.ac.in | C32: Aditya Jaiswal | D32: ="AE-"&TEXT(ROW()-1,"0000") -> AE-0031 | E32: {=IFERROR(XLOOKUP(D32,'Astronomy 101 Week 1 Quiz (Resp'!F:F,'Astronomy 101 Week 1 Quiz (Resp'!E:E),0)} -> 0 | F32: YES | H32: 9685382808 | I32: IIT Guwahati | J32: Yes | K32: Computational Module, Observational Module | L32: I want to explore space a lot and want to know the deep folded secret of space to mend my mind
A33: 46167.609 | B33: h.allu@iitg.ac.iin | C33: Allu Hemanth | D33: ="AE-"&TEXT(ROW()-1,"0000") -> AE-0032 | E33: {=IFERROR(XLOOKUP(D33,'Astronomy 101 Week 1 Quiz (Resp'!F:F,'Astronomy 101 Week 1 Quiz (Resp'!E:E),0)} -> 0 | F33: YES | H33: 8374294794 | I33: IIT Guwahati | J33: No | K33: Computational Module
A34: 46167.609 | B34: n.kinha@iitg.ac.in | C34: Nitin Kinha | D34: ="AE-"&TEXT(ROW()-1,"0000") -> AE-0033 | E34: {=IFERROR(XLOOKUP(D34,'Astronomy 101 Week 1 Quiz (Resp'!F:F,'Astronomy 101 Week 1 Quiz (Resp'!E:E),0)} -> 43 | F34: YES | H34: 9664368547 | I34: IIT GUWAHATI | J34: No | K34: Theoretical Module, Computational Module, Observational Module
A35: 46167.61 | B35: t.kritika@iitg.ac.in | C35: Kritika Tulsyan | D35: ="AE-"&TEXT(ROW()-1,"0000") -> AE-0034 | E35: {=IFERROR(XLOOKUP(D35,'Astronomy 101 Week 1 Quiz (Resp'!F:F,'Astronomy 101 Week 1 Quiz (Resp'!E:E),0)} -> 0 | F35: YES | H35: 6394937630 | I35: IITG | J35: No | K35: Observational Module | L35: To learn and explore the field of astronomy
A36: 46167.616 | B36: e.linga@iitg.ac.in | C36: LINGA RAJA E | D36: ="AE-"&TEXT(ROW()-1,"0000") -> AE-0035 | E36: {=IFERROR(XLOOKUP(D36,'Astronomy 101 Week 1 Quiz (Resp'!F:F,'Astronomy 101 Week 1 Quiz (Resp'!E:E),0)} -> 46 | F36: YES | H36: 9629645373 | I36: IITG | J36: No | K36: Computational Module, Observational Module
A37: 46167.62 | B37: j.savani@iitg.ac.in | C37: Jinen Jigneshbhai savani | D37: ="AE-"&TEXT(ROW()-1,"0000") -> AE-0036 | E37: {=IFERROR(XLOOKUP(D37,'Astronomy 101 Week 1 Quiz (Resp'!F:F,'Astronomy 101 Week 1 Quiz (Resp'!E:E),0)} -> 41 | F37: YES | H37: 9426656212 | I37: Iit guwahati | J37: No | K37: Theoretical Module, Observational Module
A38: 46167.622 | B38: mitalisahu678@gmail.com | C38: Mitali Sahu | D38: ="AE-"&TEXT(ROW()-1,"0000") -> AE-0037 | E38: {=IFERROR(XLOOKUP(D38,'Astronomy 101 Week 1 Quiz (Resp'!F:F,'Astronomy 101 Week 1 Quiz (Resp'!E:E),0)} -> 0 | F38: YES | H38: 9691120470 | I38: IIT Guwahati | J38: Yes | K38: Theoretical Module, Computational Module, Observational Module | L38: .
A39: 46167.624 | B39: m.bhatnagar@iitg.ac.in | C39: Manas bhatnagar | D39: ="AE-"&TEXT(ROW()-1,"0000") -> AE-0038 | E39: {=IFERROR(XLOOKUP(D39,'Astronomy 101 Week 1 Quiz (Resp'!F:F,'Astronomy 101 Week 1 Quiz (Resp'!E:E),0)} -> 0 | F39: YES | H39: 9317433450 | I39: IITG | J39: Yes | K39: Theoretical Module, Computational Module, Observational Module | L39: To learn exciting things and make a good base in astronomy
A40: 46167.635 | B40: v.pyata@iitg.ac.in | C40: Vipul reddy pyata | D40: ="AE-"&TEXT(ROW()-1,"0000") -> AE-0039 | E40: {=IFERROR(XLOOKUP(D40,'Astronomy 101 Week 1 Quiz (Resp'!F:F,'Astronomy 101 Week 1 Quiz (Resp'!E:E),0)} -> 30 | F40: YES | H40: 9396453012 | I40: IIT Guwahati | J40: No | K40: Theoretical Module, Computational Module, Observational Module | L40: My primary expectation from this summer course is to build a strong foundational knowledge in astronomy and astrophysics by engaging with all three modules. From the theoretical module, I hope to understand the core physics governing celestial bodies. Through the computational and observational modules, I expect to gain practical, hands-on experience with astronomical data analysis, programming tools, and telescope data interpretation. Ultimately, I want to use this comprehensive exposure to explore potential research opportunities and contribute meaningfully to the Equinox club's future initiatives.
...

Sheet Astronomy 101 Week 1 Quiz (Resp
A1: Timestamp | B1: Email Address | C1: Score | D1: Assignment Instructions Open the Colab notebook using the link below and create a copy in your Google Drive. Complete all the tasks/questions in the notebook. Once finished, make sure the sharing settings are set to "Anyone with the link can view" and paste the shareable link to your completed notebook in the response field below. Colab Notebook Link: https://colab.research.google.com/drive/1TMEWLkX_CKyG5EeCCwjXskLidoTfA4a9?usp=sharing Submission: Paste the link to your completed notebook below. | E1: Final Score | F1: Astronomy 101 Code: | G1: Name: | H1: Email id | I1: Contact Number | J1: If astronomers discovered that galaxies were moving toward us rather than away from us, how would that fundamentally change the interpretation of the following theory? | K1: For a significant portion of its early history (the Photon Epoch), the universe is described as an opaque 'soup' or fog. What key conceptual shift allowed the universe to finally become transparent to light, creating the cosmic background radiation we observe today? | L1: According to the standard Big Bang timeline, what specific fundamental force separation is hypothesised to have triggered the period of rapid exponential expansion known as cosmic inflation? | M1: During the 'Dark Ages', the universe was filled with a sea of neutral hydrogen atoms that made the cosmos opaque to shorter wavelengths of light. What mechanism fundamentally altered this state, ending the Dark Ages and allowing starlight to travel vast distances? | N1: What does the following images symbolise based on the image and time of the event | O1: Why does the Cosmic Microwave Background (CMB) appear to have a 'perfect' thermal spectrum despite space being essentially empty today? | P1: What is the fundamental difference between the 'R-process' and 'S-process' in neutron capture? | Q1: During the brief period of Big Bang nucleosynthesis, why did the universe primarily produce hydrogen and helium, rather than fusing all primordial matter into heavier, ultra-stable elements like iron? | R1: Olbers' Paradox historically asked why the night sky is dark if the universe is infinite and filled with stars. How does the Big Bang model elegantly resolve this paradox? | S1: How do neutron star mergers overcome the electrostatic repulsion that prevents standard fusion? | T1: Why are lithium, beryllium, and boron produced via cosmic ray collisions (fission) rather than typical stellar fusion? | U1: All elements are products of stardust. Do you agree? | V1: How does the birth of massive, early stars actively influence the formation of subsequent structures in the early universe? | W1: During the formation of a star, why does the inner region of the collapsing gas cloud eventually cease to collapse further and temporarily stabilize as a protostar? | X1: Identify what is present in the following image | Y1: How did the initial state of the universe during the period of quantum fluctuations ultimately dictate the large-scale distribution of matter we observe today? | Z1: In the context of large-scale galactic structures, what defines the boundaries of the "Laniakea" Supercluster, our cosmic home? | AA1: The majority of the universe's total volume is composed of what specific structural feature within the Cosmic Web? | AB1: Dark matter is an essential component of the universe's mass-energy density. Why is it impossible to observe dark matter directly using conventional optical or radio telescopes? | AC1: In contemporary physics, what is the primary observed macroscopic effect attributed to Dark Energy? | AD1: In an attempt to explain the anomalous rotation curves of galaxies without invoking unseen dark matter particles, physicists developed an alternative theory known as M.O.N.D. What does this acronym signify? | AE1: Before a star like our Sun formally initiates nuclear fusion, it spends millions of years in the "T Tauri" phase. During this pre-main-sequence stage, what is the primary source of the star's immense heat and luminosity? | AF1: Astronomers frequently measure the abundance of the element Lithium to determine the precise age of a T Tauri star. Why does the observable amount of Lithium decrease as the star ages? | AG1: What specific event definitively marks the end of the T Tauri phase and the beginning of a star's stable life on the "main sequence"? | AH1: Where do the vast majority of the universe's exceptionally heavy elements, such as gold, silver, and uranium, originate? | AI1: When an exceptionally massive star exhausts its nuclear fuel, its core violently collapses. If the remaining core mass dramatically exceeds the Tolman-Oppenheimer-Volkoff limit, what is the resulting celestial object? | AJ1: During the very early universe, a quantum process known as baryogenesis resulted in a crucial asymmetry. What was the ultimate outcome of this statistical anomaly? | AK1: If you are standing at the North Pole, where would the celestial pole be located in your sky? | AL1: Why do observers at different latitudes on Earth see the celestial pole at different heights above the horizon? | AM1: You are trying to show a friend all the different constellation drawings that are currently above your head, but Stellarium keeps making them disappear, only showing the single constellation in the middle of your screen. How do you fix this? | AN1: You want to find out what phase the moon was in on the exact night you were born. How do you achieve this in Stellarium? | AO1: Identify the following solar position | AP1: Why did the Indian Institute of Astrophysics find it necessary to establish an observatory in the Himalayan region, such as the one at Hanle, rather than relying exclusively on their existing southern observatories? | AQ1: According to the documentary in day 5, how does the creation of the Hanle Dark Sky Reserve benefit the local ecosystem, specifically the wildlife? | AR1: What will be the output of the following code? a = (1, 2, [3, 4]) a[2].append(5) print(a) | AS1: What will be the output? x = [1, 2, 3] y = x y += [4] print(x) | AT1: Which of the following can be used as a dictionary key? | AU1: What will be the output of the following code? d = {} d[(1, 2)] = "A" d[(1, 2, [3, 4])] = "B" print(len(d)) | AV1: What will be the output of the following code? a = [1, 2, 3] b = a a = a + [4] print(b) | AW1: When we tried capturing The solar position at noon for a year, what pattern did it symbolise? | AX1: Imagine you are observing the night sky from the northern hemisphere. Why are the constellations located near the summer solstice in the ecliptic path best viewed during the winter months? | AY1: Our modern map of constellations is a flat projection of a celestial sphere. What is the primary consequence of this method on the appearance of constellations at the extreme north and south poles of the map? | AZ1: Why is it often easier for a beginner to identify Jupiter in the night sky compared to Mercury? | BA1: If you were an ancient observer tracking a specific 'wandering star' that seemed to travel forward, pause, and then move backwards over several months, which celestial body would you most likely be observing? | BB1: Why is the concept of "integrated magnitude" important when observing objects like galaxies or nebulae through a telescope compared to point-like stars? | BC1: If astrology enthusiasts base their horoscopes on the zodiac, why is it scientifically misaligned with current reality?
A2: 46179.656 | B2: buralagan9@gmail.com | C2: 37 | D2: https://colab.research.google.com/drive/110-WzL0SE8DlazI8Gbo6sCxpV9Vjuc_-?usp=sharing | E2: =VALUE(LEFT(C2,FIND("/",C2)-1))+IF(D2<>"",5,0) -> 42 | F2: AE-0752 | G2: Lagan Bura | H2: buralagan9@gmail.com | I2: 9896334843 | J2: It would confirm a cyclic universe model. | K2: The cooling of the universe allowed ionized nuclei to capture electrons, neutralizing their charge and stopping them from constantly scattering photons. | L2: The separation of gravity from the unified forces at the end of the Planck Epoch. | N2: A: Merger of two galaxies during early galaxy formation B: Black Hole Formation | O2: It is the leftover light emitted by a hot, dense plasma that permeated the entire universe roughly 400,000 years after the Big Bang. | P2: The R-process involves rapid neutron accumulation before decay, leading to larger jumps in atomic mass compared to the slower S-process | R2: The universe is not infinitely old, meaning light from the most distant stars has simply not had enough time to reach us. | S2: The merger releases a massive amount of neutrons, which are then captured by atomic nuclei (the 'R-process') | T2: Because stars reach temperatures that immediately destroy these specific elements | U2: Yes, because hydrogen and helium were primarily formed during the Big Bang which later went on to become stars where other elements were created. | V2: They produce radiation that strips electrons from surrounding gas, promoting further star formation through collisions. | W2: The temperature rises until the outward kinetic energy of the gas balances the inward gravitational pull. | X2: Our home supercluster - Laniakea | Y2: Random energy spawnings caused matter to clump together, a pattern that magnified as the universe expanded. | Z2: B) A basin of attraction where the peculiar velocities of galaxies are directed inward toward a common gravitational focal point. | AA2: C) Cosmic voids, which are vast regions nearly empty of galaxies. | AB2: C) It does not interact via the electromagnetic force, meaning it neither emits, absorbs, nor reflects light. | AC2: B) It drives the accelerating, exponential expansion of the universe on large scales. | AD2: C) Modified Newtonian Dynamics | AE2: B) Gravitational energy released as the massive cloud of gas continuously contracts under its own weight. | AF2: B) Rapid rotation and convective currents drag the Lithium into the deep, hot interior of the star where it is destroyed by nuclear reactions. | AG2: D) The initiation of sustained hydrogen-to-helium nuclear fusion in the star's core. | AH2: C) They are formed during the cataclysmic explosions of supernovae and the violent mergers of neutron stars. | AI2: C) A black hole | AJ2: B) The creation of slightly more matter than antimatter (roughly one extra per billion), allowing the material universe to exist. | AK2: A) At your zenith (directly overhead). | AL2: C) Because the angle of the celestial pole correlates to the observer's latitude on the globe. | AM2: Long-press the constellations button in the bottom left and turn off the 'Centered Only' setting. | AN2: Tap the time in the bottom right, open the precise time controls, enter your birth date and time, and then locate the Moon. | AO2: Summer Solstice Sunrise | AP2: The monsoon clouds heavily affect southern India, forcing observatories to shut down for months, whereas the Himalayan ranges block these clouds, providing consistently clear skies. | AQ2: It helps preserve the natural navigation cues for migratory birds, which can otherwise be easily confused by bright artificial lighting. | AR2: (1, 2, [3, 4, 5]) | AS2: [1, 2, 3, 4] | AT2: (1, 2) | AU2: Error | AV2: [1, 2, 3] | AW2: 8 pattern | AX2: B) The sun obscures the summer solstice constellations during the summer, but during the winter, the night side of the Earth faces them. | AY2: A) They appear significantly stretched out horizontally compared to how they actually look in the night sky. | AZ2: B) Jupiter appears high in the dark night sky and is exceptionally bright, whereas Mercury is only visible very close to the horizon during sunrise or sunset and is often hidden by clouds. | BA2: C) Mars | BB2: B) Because the light of non-point objects is spread over an area, which can make them appear dimmer than their total magnitude suggests.
A3: 46179.661 | B3: varundevsr07@gmail.com | C3: 39 | E3: =VALUE(LEFT(C3,FIND("/",C3)-1))+IF(D3<>"",5,0) -> 39 | F3: AE-0999 | G3: Varun Dev S R | H3: varundevsr07@gmail.com | I3: 9400881978 | J3: It would disprove the idea that the universe originated from a single point. | K3: The cooling of the universe allowed ionized nuclei to capture electrons, neutralizing their charge and stopping them from constantly scattering photons. | L3: The separation of gravity from the unified forces at the end of the Planck Epoch. | N3: A: A Supermassive Black Hole Merger B: Black Hole Formation | O3: It is the leftover light emitted by a hot, dense plasma that permeated the entire universe roughly 400,000 years after the Big Bang. | P3: The R-process involves rapid neutron accumulation before decay, leading to larger jumps in atomic mass compared to the slower S-process | R3: The universe is not infinitely old, meaning light from the most distant stars has simply not had enough time to reach us. | S3: The merger releases a massive amount of neutrons, which are then captured by atomic nuclei (the 'R-process') | T3: Because stellar fusion processes skip over them due to their position on the binding energy curve, making them harder to fuse | U3: No, because Only elements like carbon, oxygen, neon, silicon, iron, etc. are formed from stellar synthesis except which all other elements are not directly products of stardust. | V3: They produce radiation that strips electrons from surrounding gas, promoting further star formation through collisions. | W3: The temperature rises until the outward kinetic energy of the gas balances the inward gravitational pull. | X3: Our home supercluster - Laniakea | Y3: Random energy spawnings caused matter to clump together, a pattern that magnified as the universe expanded. | Z3: B) A basin of attraction where the peculiar velocities of galaxies are directed inward toward a common gravitational focal point. | AA3: C) Cosmic voids, which are vast regions nearly empty of galaxies. | AB3: C) It does not interact via the electromagnetic force, meaning it neither emits, absorbs, nor reflects light. | AC3: B) It drives the accelerating, exponential expansion of the universe on large scales. | AD3: C) Modified Newtonian Dynamics | AE3: B) Gravitational energy released as the massive cloud of gas continuously contracts under its own weight. | AF3: B) Rapid rotation and convective currents drag the Lithium into the deep, hot interior of the star where it is destroyed by nuclear reactions. | AG3: D) The initiation of sustained hydrogen-to-helium nuclear fusion in the star's core. | AH3: C) They are formed during the cataclysmic explosions of supernovae and the violent mergers of neutron stars. | AI3: C) A black hole | AJ3: B) The creation of slightly more matter than antimatter (roughly one extra per billion), allowing the material universe to exist. | AK3: A) At your zenith (directly overhead). | AL3: C) Because the angle of the celestial pole correlates to the observer's latitude on the globe. | AM3: Long-press the constellations button in the bottom left and turn off the 'Centered Only' setting. | AN3: Tap the time in the bottom right, open the precise time controls, enter your birth date and time, and then locate the Moon. | AO3: Winter Solstice Sunrise | AP3: The monsoon clouds heavily affect southern India, forcing observatories to shut down for months, whereas the Himalayan ranges block these clouds, providing consistently clear skies. | AQ3: It helps preserve the natural navigation cues for migratory birds, which can otherwise be easily confused by bright artificial lighting. | AR3: (1, 2, [3, 4, 5]) | AS3: [1, 2, 3, 4] | AT3: (1, 2) | AU3: Error | AV3: [1, 2, 3] | AW3: 8 pattern | AX3: B) The sun obscures the summer solstice constellations during the summer, but during the winter, the night side of the Earth faces them. | AY3: A) They appear significantly stretched out horizontally compared to how they actually look in the night sky. | AZ3: B) Jupiter appears high in the dark night sky and is exceptionally bright, whereas Mercury is only visible very close to the horizon during sunrise or sunset and is often hidden by clouds. | BA3: C) Mars | BB3: B) Because the light of non-point objects is spread over an area, which can make them appear dimmer than their total magnitude suggests.
A4: 46179.663 | B4: kp9781204@gmail.com | C4: 40 | D4: https://colab.research.google.com/drive/1j7Y4coPArrJNJUoiKyHOp2C7ulHpD06I?usp=sharing | E4: =VALUE(LEFT(C4,FIND("/",C4)-1))+IF(D4<>"",5,0) -> 45 | F4: AE-0729 | G4: Kusambh Prasad | H4: kp9781204@gmail.com | I4: 6204371419 | J4: It would disprove the idea that the universe originated from a single point. | K4: The cooling of the universe allowed ionized nuclei to capture electrons, neutralizing their charge and stopping them from constantly scattering photons. | L4: The separation of gravity from the unified forces at the end of the Planck Epoch. | N4: A: Merger of two galaxies during early galaxy formation B: Black Hole Formation | O4: It is the leftover light emitted by a hot, dense plasma that permeated the entire universe roughly 400,000 years after the Big Bang. | P4: The R-process involves rapid neutron accumulation before decay, leading to larger jumps in atomic mass compared to the slower S-process | R4: The universe is not infinitely old, meaning light from the most distant stars has simply not had enough time to reach us. | S4: The merger releases a massive amount of neutrons, which are then captured by atomic nuclei (the 'R-process') | T4: Because stellar fusion processes skip over them due to their position on the binding energy curve, making them harder to fuse | U4: No, because Only elements like carbon, oxygen, neon, silicon, iron, etc. are formed from stellar synthesis except which all other elements are not directly products of stardust. | V4: They produce radiation that strips electrons from surrounding gas, promoting further star formation through collisions. | W4: The temperature rises until the outward kinetic energy of the gas balances the inward gravitational pull. | X4: Our home supercluster - Laniakea | Y4: Random energy spawnings caused matter to clump together, a pattern that magnified as the universe expanded. | Z4: B) A basin of attraction where the peculiar velocities of galaxies are directed inward toward a common gravitational focal point. | AA4: C) Cosmic voids, which are vast regions nearly empty of galaxies. | AB4: C) It does not interact via the electromagnetic force, meaning it neither emits, absorbs, nor reflects light. | AC4: B) It drives the accelerating, exponential expansion of the universe on large scales. | AD4: C) Modified Newtonian Dynamics | AE4: B) Gravitational energy released as the massive cloud of gas continuously contracts under its own weight. | AF4: B) Rapid rotation and convective currents drag the Lithium into the deep, hot interior of the star where it is destroyed by nuclear reactions. | AG4: D) The initiation of sustained hydrogen-to-helium nuclear fusion in the star's core. | AH4: C) They are formed during the cataclysmic explosions of supernovae and the violent mergers of neutron stars. | AI4: C) A black hole | AJ4: B) The creation of slightly more matter than antimatter (roughly one extra per billion), allowing the material universe to exist. | AK4: A) At your zenith (directly overhead). | AL4: C) Because the angle of the celestial pole correlates to the observer's latitude on the globe. | AM4: Long-press the constellations button in the bottom left and turn off the 'Centered Only' setting. | AN4: Tap the time in the bottom right, open the precise time controls, enter your birth date and time, and then locate the Moon. | AO4: Summer Solstice Sunrise | AP4: The monsoon clouds heavily affect southern India, forcing observatories to shut down for months, whereas the Himalayan ranges block these clouds, providing consistently clear skies. | AQ4: It helps preserve the natural navigation cues for migratory birds, which can otherwise be easily confused by bright artificial lighting. | AR4: (1, 2, [3, 4, 5]) | AS4: [1, 2, 3, 4] | AT4: (1, 2) | AU4: Error | AV4: [1, 2, 3] | AW4: 8 pattern | AX4: B) The sun obscures the summer solstice constellations during the summer, but during the winter, the night side of the Earth faces them. | AY4: A) They appear significantly stretched out horizontally compared to how they actually look in the night sky. | AZ4: B) Jupiter appears high in the dark night sky and is exceptionally bright, whereas Mercury is only visible very close to the horizon during sunrise or sunset and is often hidden by clouds. | BA4: C) Mars | BB4: B) Because the light of non-point objects is spread over an area, which can make them appear dimmer than their total magnitude suggests.
A5: 46179.677 | B5: namratau855@gmail.com | C5: 39 | D5: https://colab.research.google.com/drive/1H4HUGFM_DWFW4GKDAIXHREt_VrHxREhy?usp=sharing | E5: =VALUE(LEFT(C5,FIND("/",C5)-1))+IF(D5<>"",5,0) -> 44 | F5: AE-0976 | G5: Namrata Upadhyay | H5: namratau855@gmail.com | I5: 7394841804 | J5: It would disprove the idea that the universe originated from a single point. | K5: The cooling of the universe allowed ionized nuclei to capture electrons, neutralizing their charge and stopping them from constantly scattering photons. | L5: The separation of the strong nuclear force from the electroweak force. | N5: A: A Supermassive Black Hole Merger B: Black Hole Formation | O5: It is the leftover light emitted by a hot, dense plasma that permeated the entire universe roughly 400,000 years after the Big Bang. | P5: The R-process involves rapid neutron accumulation before decay, leading to larger jumps in atomic mass compared to the slower S-process | R5: The universe is not infinitely old, meaning light from the most distant stars has simply not had enough time to reach us. | S5: The merger releases a massive amount of neutrons, which are then captured by atomic nuclei (the 'R-process') | T5: Because stellar fusion processes skip over them due to their position on the binding energy curve, making them harder to fuse | U5: Yes, because hydrogen and helium were primarily formed during the Big Bang which later went on to become stars where other elements were created. | V5: They produce radiation that strips electrons from surrounding gas, promoting further star formation through collisions. | W5: The temperature rises until the outward kinetic energy of the gas balances the inward gravitational pull. | X5: Our home supercluster - Laniakea | Y5: Random energy spawnings caused matter to clump together, a pattern that magnified as the universe expanded. | Z5: B) A basin of attraction where the peculiar velocities of galaxies are directed inward toward a common gravitational focal point. | AA5: C) Cosmic voids, which are vast regions nearly empty of galaxies. | AB5: C) It does not interact via the electromagnetic force, meaning it neither emits, absorbs, nor reflects light. | AC5: B) It drives the accelerating, exponential expansion of the universe on large scales. | AD5: C) Modified Newtonian Dynamics | AE5: B) Gravitational energy released as the massive cloud of gas continuously contracts under its own weight. | AF5: B) Rapid rotation and convective currents drag the Lithium into the deep, hot interior of the star where it is destroyed by nuclear reactions. | AG5: D) The initiation of sustained hydrogen-to-helium nuclear fusion in the star's core. | AH5: C) They are formed during the cataclysmic explosions of supernovae and the violent mergers of neutron stars. | AI5: C) A black hole | AJ5: B) The creation of slightly more matter than antimatter (roughly one extra per billion), allowing the material universe to exist. | AK5: A) At your zenith (directly overhead). | AL5: C) Because the angle of the celestial pole correlates to the observer's latitude on the globe. | AM5: Long-press the constellations button in the bottom left and turn off the 'Centered Only' setting. | AN5: Tap the time in the bottom right, open the precise time controls, enter your birth date and time, and then locate the Moon. | AO5: Equinox Sunrise | AP5: The monsoon clouds heavily affect southern India, forcing observatories to shut down for months, whereas the Himalayan ranges block these clouds, providing consistently clear skies. | AQ5: It helps preserve the natural navigation cues for migratory birds, which can otherwise be easily confused by bright artificial lighting. | AR5: (1, 2, [3, 4, 5]) | AS5: [1, 2, 3, 4] | AT5: (1, 2) | AU5: Error | AV5: [1, 2, 3] | AW5: ∞ pattrn | AX5: B) The sun obscures the summer solstice constellations during the summer, but during the winter, the night side of the Earth faces them. | AY5: A) They appear significantly stretched out horizontally compared to how they actually look in the night sky. | AZ5: B) Jupiter appears high in the dark night sky and is exceptionally bright, whereas Mercury is only visible very close to the horizon during sunrise or sunset and is often hidden by clouds. | BA5: C) Mars | BB5: B) Because the light of non-point objects is spread over an area, which can make them appear dimmer than their total magnitude suggests.
A6: 46179.689 | B6: surya280907@gmail.com | C6: 25 | E6: =VALUE(LEFT(C6,FIND("/",C6)-1))+IF(D6<>"",5,0) -> 25 | F6: AE-0985 | G6: Surya S P | H6: surya280907@gmail.com | I6: 8122217371 | J6: It would have no impact on the Big Bang theory. | K6: The cooling of the universe allowed ionized nuclei to capture electrons, neutralizing their charge and stopping them from constantly scattering photons. | L6: The separation of the strong nuclear force from the electroweak force. | N6: A: A Supermassive Black Hole Merger B: Black Hole Formation | O6: It is the leftover light emitted by a hot, dense plasma that permeated the entire universe roughly 400,000 years after the Big Bang. | P6: The R-process involves rapid neutron accumulation before decay, leading to larger jumps in atomic mass compared to the slower S-process | R6: The universe is not infinitely old, meaning light from the most distant stars has simply not had enough time to reach us. | S6: The merger releases a massive amount of neutrons, which are then captured by atomic nuclei (the 'R-process') | T6: Because stellar fusion processes skip over them due to their position on the binding energy curve, making them harder to fuse | U6: Yes, because hydrogen and helium were primarily formed during the Big Bang which later went on to become stars where other elements were created. | V6: They produce radiation that strips electrons from surrounding gas, promoting further star formation through collisions. | W6: The temperature rises until the outward kinetic energy of the gas balances the inward gravitational pull. | X6: Our home supercluster - Laniakea | Y6: Random energy spawnings caused matter to clump together, a pattern that magnified as the universe expanded. | Z6: B) A basin of attraction where the peculiar velocities of galaxies are directed inward toward a common gravitational focal point. | AA6: C) Cosmic voids, which are vast regions nearly empty of galaxies. | AB6: C) It does not interact via the electromagnetic force, meaning it neither emits, absorbs, nor reflects light. | AC6: B) It drives the accelerating, exponential expansion of the universe on large scales. | AD6: C) Modified Newtonian Dynamics | AE6: B) Gravitational energy released as the massive cloud of gas continuously contracts under its own weight. | AF6: B) Rapid rotation and convective currents drag the Lithium into the deep, hot interior of the star where it is destroyed by nuclear reactions. | AG6: D) The initiation of sustained hydrogen-to-helium nuclear fusion in the star's core. | AH6: C) They are formed during the cataclysmic explosions of supernovae and the violent mergers of neutron stars. | AI6: C) A black hole | AJ6: B) The creation of slightly more matter than antimatter (roughly one extra per billion), allowing the material universe to exist. | AR6: (1, 2, [3, 4, 5]) | AS6: [1, 2, 3, 4] | AT6: {"a": 1} | AU6: Error | AV6: [1, 2, 3]
A7: 46179.705 | B7: dhairya1101@iitg.ac.in | C7: 41 | D7: https://colab.research.google.com/drive/1-pucxgA-o-cF20V9SC3gz5FXclCvMVuk?usp=sharing | E7: =VALUE(LEFT(C7,FIND("/",C7)-1))+IF(D7<>"",5,0) -> 46 | F7: AE-0265 | G7: Dhairya | H7: dhairya1101@iitg.ac.in | I7: 8630225566 | J7: It would disprove the idea that the universe originated from a single point. | K7: The cooling of the universe allowed ionized nuclei to capture electrons, neutralizing their charge and stopping them from constantly scattering photons. | L7: The separation of the strong nuclear force from the electroweak force. | N7: A: Merger of two galaxies during early galaxy formation B: Black Hole Formation | O7: It is the leftover light emitted by a hot, dense plasma that permeated the entire universe roughly 400,000 years after the Big Bang. | P7: The R-process involves rapid neutron accumulation before decay, leading to larger jumps in atomic mass compared to the slower S-process | R7: The universe is not infinitely old, meaning light from the most distant stars has simply not had enough time to reach us. | S7: The merger releases a massive amount of neutrons, which are then captured by atomic nuclei (the 'R-process') | T7: Because stellar fusion processes skip over them due to their position on the binding energy curve, making them harder to fuse | U7: No, because Only elements like carbon, oxygen, neon, silicon, iron, etc. are formed from stellar synthesis except which all other elements are not directly products of stardust. | V7: They produce radiation that strips electrons from surrounding gas, promoting further star formation through collisions. | W7: The temperature rises until the outward kinetic energy of the gas balances the inward gravitational pull. | X7: Our home supercluster - Laniakea | Y7: Random energy spawnings caused matter to clump together, a pattern that magnified as the universe expanded. | Z7: B) A basin of attraction where the peculiar velocities of galaxies are directed inward toward a common gravitational focal point. | AA7: C) Cosmic voids, which are vast regions nearly empty of galaxies. | AB7: C) It does not interact via the electromagnetic force, meaning it neither emits, absorbs, nor reflects light. | AC7: B) It drives the accelerating, exponential expansion of the universe on large scales. | AD7: C) Modified Newtonian Dynamics | AE7: B) Gravitational energy released as the massive cloud of gas continuously contracts under its own weight. | AF7: B) Rapid rotation and convective currents drag the Lithium into the deep, hot interior of the star where it is destroyed by nuclear reactions. | AG7: D) The initiation of sustained hydrogen-to-helium nuclear fusion in the star's core. | AH7: C) They are formed during the cataclysmic explosions of supernovae and the violent mergers of neutron stars. | AI7: C) A black hole | AJ7: B) The creation of slightly more matter than antimatter (roughly one extra per billion), allowing the material universe to exist. | AK7: A) At your zenith (directly overhead). | AL7: C) Because the angle of the celestial pole correlates to the observer's latitude on the globe. | AM7: Long-press the constellations button in the bottom left and turn off the 'Centered Only' setting. | AN7: Tap the time in the bottom right, open the precise time controls, enter your birth date and time, and then locate the Moon. | AO7: Equinox Sunrise | AP7: The monsoon clouds heavily affect southern India, forcing observatories to shut down for months, whereas the Himalayan ranges block these clouds, providing consistently clear skies. | AQ7: It helps preserve the natural navigation cues for migratory birds, which can otherwise be easily confused by bright artificial lighting. | AR7: (1, 2, [3, 4, 5]) | AS7: [1, 2, 3, 4] | AT7: (1, 2) | AU7: Error | AV7: [1, 2, 3] | AW7: ∞ pattrn | AX7: B) The sun obscures the summer solstice constellations during the summer, but during the winter, the night side of the Earth faces them. | AY7: A) They appear significantly stretched out horizontally compared to how they actually look in the night sky. | AZ7: B) Jupiter appears high in the dark night sky and is exceptionally bright, whereas Mercury is only visible very close to the horizon during sunrise or sunset and is often hidden by clouds. | BA7: C) Mars | BB7: B) Because the light of non-point objects is spread over an area, which can make them appear dimmer than their total magnitude suggests.
A8: 46179.709 | B8: jinumehta12@gmail.com | C8: 39 | D8: https://colab.research.google.com/drive/1Fb5fobzOQ_J6oXX-UCAyHwfbvzB6XomE?usp=sharing | E8: =VALUE(LEFT(C8,FIND("/",C8)-1))+IF(D8<>"",5,0) -> 44 | F8: AE-0004 | G8: Jinay Mehta | H8: m.jinay@iitg.ac.in | I8: 7575842118 | J8: It would disprove the idea that the universe originated from a single point. | K8: The cooling of the universe allowed ionized nuclei to capture electrons, neutralizing their charge and stopping them from constantly scattering photons. | L8: The separation of the strong nuclear force from the electroweak force. | N8: A: Merger of two galaxies during early galaxy formation B: Death of a star | O8: It is the leftover light emitted by a hot, dense plasma that permeated the entire universe roughly 400,000 years after the Big Bang. | P8: The R-process involves rapid neutron accumulation before decay, leading to larger jumps in atomic mass compared to the slower S-process | R8: The universe is not infinitely old, meaning light from the most distant stars has simply not had enough time to reach us. | S8: The merger releases a massive amount of neutrons, which are then captured by atomic nuclei (the 'R-process') | T8: Because stellar fusion processes skip over them due to their position on the binding energy curve, making them harder to fuse | U8: Yes, because hydrogen and helium were primarily formed during the Big Bang which later went on to become stars where other elements were created. | V8: They produce radiation that strips electrons from surrounding gas, promoting further star formation through collisions. | W8: The temperature rises until the outward kinetic energy of the gas balances the inward gravitational pull. | X8: Our home supercluster - Laniakea | Y8: Random energy spawnings caused matter to clump together, a pattern that magnified as the universe expanded. | Z8: B) A basin of attraction where the peculiar velocities of galaxies are directed inward toward a common gravitational focal point. | AA8: C) Cosmic voids, which are vast regions nearly empty of galaxies. | AB8: C) It does not interact via the electromagnetic force, meaning it neither emits, absorbs, nor reflects light. | AC8: B) It drives the accelerating, exponential expansion of the universe on large scales. | AD8: C) Modified Newtonian Dynamics | AE8: B) Gravitational energy released as the massive cloud of gas continuously contracts under its own weight. | AF8: B) Rapid rotation and convective currents drag the Lithium into the deep, hot interior of the star where it is destroyed by nuclear reactions. | AG8: D) The initiation of sustained hydrogen-to-helium nuclear fusion in the star's core. | AH8: C) They are formed during the cataclysmic explosions of supernovae and the violent mergers of neutron stars. | AI8: C) A black hole | AJ8: B) The creation of slightly more matter than antimatter (roughly one extra per billion), allowing the material universe to exist. | AK8: A) At your zenith (directly overhead). | AL8: C) Because the angle of the celestial pole correlates to the observer's latitude on the globe. | AM8: Long-press the constellations button in the bottom left and turn off the 'Centered Only' setting. | AN8: Tap the time in the bottom right, open the precise time controls, enter your birth date and time, and then locate the Moon. | AO8: Equinox Sunrise | AP8: The monsoon clouds heavily affect southern India, forcing observatories to shut down for months, whereas the Himalayan ranges block these clouds, providing consistently clear skies. | AQ8: It helps preserve the natural navigation cues for migratory birds, which can otherwise be easily confused by bright artificial lighting. | AR8: (1, 2, [3, 4, 5]) | AS8: [1, 2, 3, 4] | AT8: (1, 2) | AU8: Error | AV8: [1, 2, 3] | AW8: 8 pattern | AX8: B) The sun obscures the summer solstice constellations during the summer, but during the winter, the night side of the Earth faces them. | AY8: B) They appear much smaller and squished together compared to the constellations near the celestial equator. | AZ8: B) Jupiter appears high in the dark night sky and is exceptionally bright, whereas Mercury is only visible very close to the horizon during sunrise or sunset and is often hidden by clouds. | BA8: C) Mars | BB8: B) Because the light of non-point objects is spread over an area, which can make them appear dimmer than their total magnitude suggests.
A9: 46179.724 | B9: gaurav.jowhry1@gmail.com | C9: 34 | D9: https://colab.research.google.com/drive/141QztwmBKFnicLDchJ4sDuRKggJdiS_T | E9: =VALUE(LEFT(C9,FIND("/",C9)-1))+IF(D9<>"",5,0) -> 39 | F9: AE-0920 | G9: Aishwary Datt jowhry | H9: a.jowhry@iitg.ac.in | I9: 9717840802 | J9: It would confirm a cyclic universe model. | K9: The cooling of the universe allowed ionized nuclei to capture electrons, neutralizing their charge and stopping them from constantly scattering photons. | L9: The separation of the strong nuclear force from the electroweak force. | N9: A: Merger of two galaxies during early galaxy formation B: Black Hole Formation | O9: It is the leftover light emitted by a hot, dense plasma that permeated the entire universe roughly 400,000 years after the Big Bang. | P9: The R-process involves rapid neutron accumulation before decay, leading to larger jumps in atomic mass compared to the slower S-process | R9: The expansion of the universe compresses visible light into invisible gamma rays. | S9: The merger releases a massive amount of neutrons, which are then captured by atomic nuclei (the 'R-process') | T9: Because stars reach temperatures that immediately destroy these specific elements | U9: No, because Only elements like carbon, oxygen, neon, silicon, iron, etc. are formed from stellar synthesis except which all other elements are not directly products of stardust. | V9: They produce radiation that strips electrons from surrounding gas, promoting further star formation through collisions. | W9: The rotation of the cloud creates a centrifugal force that counteracts gravity. | X9: Our home supercluster - Laniakea | Y9: They generated rapid sequences of stellar formation that consumed all nearby matter immediately. | Z9: B) A basin of attraction where the peculiar velocities of galaxies are directed inward toward a common gravitational focal point. | AA9: C) Cosmic voids, which are vast regions nearly empty of galaxies. | AB9: C) It does not interact via the electromagnetic force, meaning it neither emits, absorbs, nor reflects light. | AC9: B) It drives the accelerating, exponential expansion of the universe on large scales. | AD9: C) Modified Newtonian Dynamics | AE9: B) Gravitational energy released as the massive cloud of gas continuously contracts under its own weight. | AF9: B) Rapid rotation and convective currents drag the Lithium into the deep, hot interior of the star where it is destroyed by nuclear reactions. | AG9: D) The initiation of sustained hydrogen-to-helium nuclear fusion in the star's core. | AH9: C) They are formed during the cataclysmic explosions of supernovae and the violent mergers of neutron stars. | AI9: C) A black hole | AJ9: B) The creation of slightly more matter than antimatter (roughly one extra per billion), allowing the material universe to exist. | AK9: A) At your zenith (directly overhead). | AL9: C) Because the angle of the celestial pole correlates to the observer's latitude on the globe. | AM9: Long-press the constellations button in the bottom left and turn off the 'Centered Only' setting. | AN9: Tap the time in the bottom right, open the precise time controls, enter your birth date and time, and then locate the Moon. | AO9: Equinox Sunrise | AP9: The light pollution in southern India has completely blinded the telescopes, making it permanently impossible to view any stars. | AQ9: It helps preserve the natural navigation cues for migratory birds, which can otherwise be easily confused by bright artificial lighting. | AR9: (1, 2, [3, 4, 5]) | AS9: [1, 2, 3, 4] | AT9: [1, 2] | AU9: Error | AV9: [1, 2, 3] | AW9: 8 pattern | AX9: B) The sun obscures the summer solstice constellations during the summer, but during the winter, the night side of the Earth faces them. | AY9: B) They appear much smaller and squished together compared to the constellations near the celestial equator. | AZ9: B) Jupiter appears high in the dark night sky and is exceptionally bright, whereas Mercury is only visible very close to the horizon during sunrise or sunset and is often hidden by clouds. | BA9: A) Venus | BB9: B) Because the light of non-point objects is spread over an area, which can make them appear dimmer than their total magnitude suggests.
